Workbook

Sheet Dashboard
A1: Column0 | B1: Consulter spreadsheet
B2: START DATE (FORMAT M/DD/YYYY) (IF NONE TODAY): | C2: 01/31/2026 | D2: Please do not use the C2 cell. Thank you.
D3: Instead use the loop at the top-right of the window.
B5: PRODUIT | C5: Month | G5: Year to date | K5: Year to year
C6: N - 1 | D6: {=Quantity!O6} -> #VALUE! | E6: N | F6: {=Quantity!C6} -> #VALUE! | G6: N-1 | H6: {="09/"&YEAR(EDATE(Quantity!$C$3,-20))} -> #VALUE! | I6: N | J6: {="09/"&YEAR(EDATE(Quantity!$C$3,-8))} -> #VALUE! | K6: N-1 | L6: {=Quantity!Z6&" - "&Quantity!O6} -> #VALUE! | M6: N | N6: {=Quantity!N6&" - "&Quantity!C6} -> #VALUE!
C7: Quant | D7: TO | E7: Quant | F7: TO | G7: Quant | H7: TO | I7: Quant | J7: TO | K7: Quant | L7: TO | M7: Quant | N7: TO
A8: Column0 | B8: TOTAL | C8: 116 | D8: 38,984€ | E8: 118 | F8: 36,718€ | G8: 594 | H8: 183,643€ | I8: 598 | J8: 183,034€ | K8: 1,497 | L8: 467,880€ | M8: 1,470 | N8: 455,409€
B9: {=Quantity!B11} -> [#417996] ADIAVET™ MYCO AV REAL TIME | C9: {=Quantity!O11} -> 0 | D9: {=CA!O11} -> 0 | E9: {=Quantity!C11} -> 0 | F9: {=CA!C11} -> 0 | G9: {=SUMIFS(Quantity!$C11:$AH11,Quantity!$C$7:$AH$7,H$6,Quantity!$C$8:$AH$8,TRUE)} -> 0 | H9: {=SUMIFS(CA!$C11:$AQ11,CA!$C$7:$AQ$7,H$6,CA!$C$8:$AQ$8,TRUE)} -> 0 | I9: {=SUMIFS(Quantity!$C11:$AH11,Quantity!$C$7:$AH$7,J$6,Quantity!$C$8:$AH$8,TRUE)} -> 0 | J9: {=SUMIFS(CA!$C11:$AQ11,CA!$C$7:$AQ$7,J$6,CA!$C$8:$AQ$8,TRUE)} -> 0 | K9: {=IF(SUM(Quantity!O11:Z11)=0,"",SUM(Quantity!O11:Z11))} | L9: {=IF(SUM(CA!O11:Z11)=0,"",SUM(CA!O11:Z11))} | M9: {=IF(SUM(Quantity!C11:N11)=0,"",SUM(Quantity!C11:N11))} | N9: {=IF(SUM(CA!C11:N11)=0,"",SUM(CA!C11:N11))}
B10: {=Quantity!B12} -> [#418020] ADIAVET™ LAW REAL TIME | C10: {=Quantity!O12} -> 0 | D10: {=CA!O12} -> 0 | E10: {=Quantity!C12} -> 0 | F10: {=CA!C12} -> 0 | G10: {=SUMIFS(Quantity!$C12:$AH12,Quantity!$C$7:$AH$7,H$6,Quantity!$C$8:$AH$8,TRUE)} -> 0 | H10: {=SUMIFS(CA!$C12:$AQ12,CA!$C$7:$AQ$7,H$6,CA!$C$8:$AQ$8,TRUE)} -> 0 | I10: {=SUMIFS(Quantity!$C12:$AH12,Quantity!$C$7:$AH$7,J$6,Quantity!$C$8:$AH$8,TRUE)} -> 0 | J10: {=SUMIFS(CA!$C12:$AQ12,CA!$C$7:$AQ$7,J$6,CA!$C$8:$AQ$8,TRUE)} -> 0 | K10: {=IF(SUM(Quantity!O12:Z12)=0,"",SUM(Quantity!O12:Z12))} -> 6 | L10: {=IF(SUM(CA!O12:Z12)=0,"",SUM(CA!O12:Z12))} -> 6049.8 | M10: {=IF(SUM(Quantity!C12:N12)=0,"",SUM(Quantity!C12:N12))} | N10: {=IF(SUM(CA!C12:N12)=0,"",SUM(CA!C12:N12))}
B11: {=Quantity!B13} -> [#418021] ADIAVET™ BRACHY REAL TIME | C11: {=Quantity!O13} -> 0 | D11: {=CA!O13} -> 0 | E11: {=Quantity!C13} -> 0 | F11: {=CA!C13} -> 0 | G11: {=SUMIFS(Quantity!$C13:$AH13,Quantity!$C$7:$AH$7,H$6,Quantity!$C$8:$AH$8,TRUE)} -> 0 | H11: {=SUMIFS(CA!$C13:$AQ13,CA!$C$7:$AQ$7,H$6,CA!$C$8:$AQ$8,TRUE)} -> 0 | I11: {=SUMIFS(Quantity!$C13:$AH13,Quantity!$C$7:$AH$7,J$6,Quantity!$C$8:$AH$8,TRUE)} -> 0 | J11: {=SUMIFS(CA!$C13:$AQ13,CA!$C$7:$AQ$7,J$6,CA!$C$8:$AQ$8,TRUE)} -> 0 | K11: {=IF(SUM(Quantity!O13:Z13)=0,"",SUM(Quantity!O13:Z13))} -> 1 | L11: {=IF(SUM(CA!O13:Z13)=0,"",SUM(CA!O13:Z13))} -> 983.7 | M11: {=IF(SUM(Quantity!C13:N13)=0,"",SUM(Quantity!C13:N13))} -> 2 | N11: {=IF(SUM(CA!C13:N13)=0,"",SUM(CA!C13:N13))} -> 1899
B12: {=Quantity!B14} -> [#418022] ADIAVET™ M.HYOP REAL TIME | C12: {=Quantity!O14} -> 0 | D12: {=CA!O14} -> 0 | E12: {=Quantity!C14} -> 0 | F12: {=CA!C14} -> 0 | G12: {=SUMIFS(Quantity!$C14:$AH14,Quantity!$C$7:$AH$7,H$6,Quantity!$C$8:$AH$8,TRUE)} -> 0 | H12: {=SUMIFS(CA!$C14:$AQ14,CA!$C$7:$AQ$7,H$6,CA!$C$8:$AQ$8,TRUE)} -> 0 | I12: {=SUMIFS(Quantity!$C14:$AH14,Quantity!$C$7:$AH$7,J$6,Quantity!$C$8:$AH$8,TRUE)} -> 0 | J12: {=SUMIFS(CA!$C14:$AQ14,CA!$C$7:$AQ$7,J$6,CA!$C$8:$AQ$8,TRUE)} -> 0 | K12: {=IF(SUM(Quantity!O14:Z14)=0,"",SUM(Quantity!O14:Z14))} -> 1 | L12: {=IF(SUM(CA!O14:Z14)=0,"",SUM(CA!O14:Z14))} -> 927 | M12: {=IF(SUM(Quantity!C14:N14)=0,"",SUM(Quantity!C14:N14))} | N12: {=IF(SUM(CA!C14:N14)=0,"",SUM(CA!C14:N14))}
B13: {=Quantity!B15} -> [#418023] ADIAVET™ NEOSPORA REAL TIME | C13: {=Quantity!O15} -> 0 | D13: {=CA!O15} -> 0 | E13: {=Quantity!C15} -> 0 | F13: {=CA!C15} -> 0 | G13: {=SUMIFS(Quantity!$C15:$AH15,Quantity!$C$7:$AH$7,H$6,Quantity!$C$8:$AH$8,TRUE)} -> 0 | H13: {=SUMIFS(CA!$C15:$AQ15,CA!$C$7:$AQ$7,H$6,CA!$C$8:$AQ$8,TRUE)} -> 0 | I13: {=SUMIFS(Quantity!$C15:$AH15,Quantity!$C$7:$AH$7,J$6,Quantity!$C$8:$AH$8,TRUE)} -> 0 | J13: {=SUMIFS(CA!$C15:$AQ15,CA!$C$7:$AQ$7,J$6,CA!$C$8:$AQ$8,TRUE)} -> 0 | K13: {=IF(SUM(Quantity!O15:Z15)=0,"",SUM(Quantity!O15:Z15))} -> 3 | L13: {=IF(SUM(CA!O15:Z15)=0,"",SUM(CA!O15:Z15))} -> 840 | M13: {=IF(SUM(Quantity!C15:N15)=0,"",SUM(Quantity!C15:N15))} -> 2 | N13: {=IF(SUM(CA!C15:N15)=0,"",SUM(CA!C15:N15))} -> 560
B14: {=Quantity!B16} -> [#418024] ADIAVET™ CHLAM.A. REAL TIME | C14: {=Quantity!O16} -> 0 | D14: {=CA!O16} -> 0 | E14: {=Quantity!C16} -> 0 | F14: {=CA!C16} -> 0 | G14: {=SUMIFS(Quantity!$C16:$AH16,Quantity!$C$7:$AH$7,H$6,Quantity!$C$8:$AH$8,TRUE)} -> 0 | H14: {=SUMIFS(CA!$C16:$AQ16,CA!$C$7:$AQ$7,H$6,CA!$C$8:$AQ$8,TRUE)} -> 0 | I14: {=SUMIFS(Quantity!$C16:$AH16,Quantity!$C$7:$AH$7,J$6,Quantity!$C$8:$AH$8,TRUE)} -> 0 | J14: {=SUMIFS(CA!$C16:$AQ16,CA!$C$7:$AQ$7,J$6,CA!$C$8:$AQ$8,TRUE)} -> 0 | K14: {=IF(SUM(Quantity!O16:Z16)=0,"",SUM(Quantity!O16:Z16))} -> 4 | L14: {=IF(SUM(CA!O16:Z16)=0,"",SUM(CA!O16:Z16))} -> 1120 | M14: {=IF(SUM(Quantity!C16:N16)=0,"",SUM(Quantity!C16:N16))} -> 2 | N14: {=IF(SUM(CA!C16:N16)=0,"",SUM(CA!C16:N16))} -> 560
B15: {=Quantity!B17} -> [#418026] ADIAVET™ LEPTO REAL TIME | C15: {=Quantity!O17} -> 4 | D15: {=CA!O17} -> 2200 | E15: {=Quantity!C17} -> 4 | F15: {=CA!C17} -> 2200 | G15: {=SUMIFS(Quantity!$C17:$AH17,Quantity!$C$7:$AH$7,H$6,Quantity!$C$8:$AH$8,TRUE)} -> 0 | H15: {=SUMIFS(CA!$C17:$AQ17,CA!$C$7:$AQ$7,H$6,CA!$C$8:$AQ$8,TRUE)} -> 0 | I15: {=SUMIFS(Quantity!$C17:$AH17,Quantity!$C$7:$AH$7,J$6,Quantity!$C$8:$AH$8,TRUE)} -> 0 | J15: {=SUMIFS(CA!$C17:$AQ17,CA!$C$7:$AQ$7,J$6,CA!$C$8:$AQ$8,TRUE)} -> 0 | K15: {=IF(SUM(Quantity!O17:Z17)=0,"",SUM(Quantity!O17:Z17))} -> 22 | L15: {=IF(SUM(CA!O17:Z17)=0,"",SUM(CA!O17:Z17))} -> 12100 | M15: {=IF(SUM(Quantity!C17:N17)=0,"",SUM(Quantity!C17:N17))} -> 31 | N15: {=IF(SUM(CA!C17:N17)=0,"",SUM(CA!C17:N17))} -> 16850
B16: {=Quantity!B18} -> [#418027] ADIAVET™ TOXO REAL TIME | C16: {=Quantity!O18} -> 0 | D16: {=CA!O18} -> 0 | E16: {=Quantity!C18} -> 0 | F16: {=CA!C18} -> 0 | G16: {=SUMIFS(Quantity!$C18:$AH18,Quantity!$C$7:$AH$7,H$6,Quantity!$C$8:$AH$8,TRUE)} -> 0 | H16: {=SUMIFS(CA!$C18:$AQ18,CA!$C$7:$AQ$7,H$6,CA!$C$8:$AQ$8,TRUE)} -> 0 | I16: {=SUMIFS(Quantity!$C18:$AH18,Quantity!$C$7:$AH$7,J$6,Quantity!$C$8:$AH$8,TRUE)} -> 0 | J16: {=SUMIFS(CA!$C18:$AQ18,CA!$C$7:$AQ$7,J$6,CA!$C$8:$AQ$8,TRUE)} -> 0 | K16: {=IF(SUM(Quantity!O18:Z18)=0,"",SUM(Quantity!O18:Z18))} | L16: {=IF(SUM(CA!O18:Z18)=0,"",SUM(CA!O18:Z18))} | M16: {=IF(SUM(Quantity!C18:N18)=0,"",SUM(Quantity!C18:N18))} | N16: {=IF(SUM(CA!C18:N18)=0,"",SUM(CA!C18:N18))}
B17: {=Quantity!B10} -> [ADPREP-100] ADIAPREP™ 100 | C17: {=Quantity!O10} -> 0 | D17: {=CA!O10} -> 0 | E17: {=Quantity!C10} -> 0 | F17: {=CA!C10} -> 0 | G17: {=SUMIFS(Quantity!$C10:$AH10,Quantity!$C$7:$AH$7,H$6,Quantity!$C$8:$AH$8,TRUE)} -> 0 | H17: {=SUMIFS(CA!$C10:$AQ10,CA!$C$7:$AQ$7,H$6,CA!$C$8:$AQ$8,TRUE)} -> 0 | I17: {=SUMIFS(Quantity!$C10:$AH10,Quantity!$C$7:$AH$7,J$6,Quantity!$C$8:$AH$8,TRUE)} -> 0 | J17: {=SUMIFS(CA!$C10:$AQ10,CA!$C$7:$AQ$7,J$6,CA!$C$8:$AQ$8,TRUE)} -> 0 | K17: {=IF(SUM(Quantity!O10:Z10)=0,"",SUM(Quantity!O10:Z10))} | L17: {=IF(SUM(CA!O10:Z10)=0,"",SUM(CA!O10:Z10))} | M17: {=IF(SUM(Quantity!C10:N10)=0,"",SUM(Quantity!C10:N10))} -> 1 | N17: {=IF(SUM(CA!C10:N10)=0,"",SUM(CA!C10:N10))} -> 185
B18: {=Quantity!B19} -> [#418028] ADIAVET™ ANA PHA REAL TIME | C18: {=Quantity!O19} -> 1 | D18: {=CA!O19} -> 350 | E18: {=Quantity!C19} -> 3 | F18: {=CA!C19} -> 1050 | G18: {=SUMIFS(Quantity!$C19:$AH19,Quantity!$C$7:$AH$7,H$6,Quantity!$C$8:$AH$8,TRUE)} -> 0 | H18: {=SUMIFS(CA!$C19:$AQ19,CA!$C$7:$AQ$7,H$6,CA!$C$8:$AQ$8,TRUE)} -> 0 | I18: {=SUMIFS(Quantity!$C19:$AH19,Quantity!$C$7:$AH$7,J$6,Quantity!$C$8:$AH$8,TRUE)} -> 0 | J18: {=SUMIFS(CA!$C19:$AQ19,CA!$C$7:$AQ$7,J$6,CA!$C$8:$AQ$8,TRUE)} -> 0 | K18: {=IF(SUM(Quantity!O19:Z19)=0,"",SUM(Quantity!O19:Z19))} -> 29 | L18: {=IF(SUM(CA!O19:Z19)=0,"",SUM(CA!O19:Z19))} -> 10150 | M18: {=IF(SUM(Quantity!C19:N19)=0,"",SUM(Quantity!C19:N19))} -> 46 | N18: {=IF(SUM(CA!C19:N19)=0,"",SUM(CA!C19:N19))} -> 16900
B19: {=Quantity!B20} -> [ADC04SQ01] Adiacontrol Quantified Extraction Positive Control Paratb Faeces | C19: {=Quantity!O20} -> 0 | D19: {=CA!O20} -> 0 | E19: {=Quantity!C20} -> 0 | F19: {=CA!C20} -> 0 | G19: {=SUMIFS(Quantity!$C20:$AH20,Quantity!$C$7:$AH$7,H$6,Quantity!$C$8:$AH$8,TRUE)} -> 0 | H19: {=SUMIFS(CA!$C20:$AQ20,CA!$C$7:$AQ$7,H$6,CA!$C$8:$AQ$8,TRUE)} -> 0 | I19: {=SUMIFS(Quantity!$C20:$AH20,Quantity!$C$7:$AH$7,J$6,Quantity!$C$8:$AH$8,TRUE)} -> 0 | J19: {=SUMIFS(CA!$C20:$AQ20,CA!$C$7:$AQ$7,J$6,CA!$C$8:$AQ$8,TRUE)} -> 0 | K19: {=IF(SUM(Quantity!O20:Z20)=0,"",SUM(Quantity!O20:Z20))} | L19: {=IF(SUM(CA!O20:Z20)=0,"",SUM(CA!O20:Z20))} | M19: {=IF(SUM(Quantity!C20:N20)=0,"",SUM(Quantity!C20:N20))} -> 2 | N19: {=IF(SUM(CA!C20:N20)=0,"",SUM(CA!C20:N20))}
B20: {=Quantity!B21} -> [ADC10S02] Adiacontrol Extraction Positive Control BVDV EAR | C20: {=Quantity!O21} -> 0 | D20: {=CA!O21} -> 0 | E20: {=Quantity!C21} -> 0 | F20: {=CA!C21} -> 0 | G20: {=SUMIFS(Quantity!$C21:$AH21,Quantity!$C$7:$AH$7,H$6,Quantity!$C$8:$AH$8,TRUE)} -> 0 | H20: {=SUMIFS(CA!$C21:$AQ21,CA!$C$7:$AQ$7,H$6,CA!$C$8:$AQ$8,TRUE)} -> 0 | I20: {=SUMIFS(Quantity!$C21:$AH21,Quantity!$C$7:$AH$7,J$6,Quantity!$C$8:$AH$8,TRUE)} -> 0 | J20: {=SUMIFS(CA!$C21:$AQ21,CA!$C$7:$AQ$7,J$6,CA!$C$8:$AQ$8,TRUE)} -> 0 | K20: {=IF(SUM(Quantity!O21:Z21)=0,"",SUM(Quantity!O21:Z21))} -> 1 | L20: {=IF(SUM(CA!O21:Z21)=0,"",SUM(CA!O21:Z21))} | M20: {=IF(SUM(Quantity!C21:N21)=0,"",SUM(Quantity!C21:N21))} -> 1 | N20: {=IF(SUM(CA!C21:N21)=0,"",SUM(CA!C21:N21))}
B21: {=Quantity!B22} -> [ADI016-100] ADIAVET™ MYCO AV FAST TIME | C21: {=Quantity!O22} -> 0 | D21: {=CA!O22} -> 0 | E21: {=Quantity!C22} -> 1 | F21: {=CA!C22} -> 400 | G21: {=SUMIFS(Quantity!$C22:$AH22,Quantity!$C$7:$AH$7,H$6,Quantity!$C$8:$AH$8,TRUE)} -> 0 | H21: {=SUMIFS(CA!$C22:$AQ22,CA!$C$7:$AQ$7,H$6,CA!$C$8:$AQ$8,TRUE)} -> 0 | I21: {=SUMIFS(Quantity!$C22:$AH22,Quantity!$C$7:$AH$7,J$6,Quantity!$C$8:$AH$8,TRUE)} -> 0 | J21: {=SUMIFS(CA!$C22:$AQ22,CA!$C$7:$AQ$7,J$6,CA!$C$8:$AQ$8,TRUE)} -> 0 | K21: {=IF(SUM(Quantity!O22:Z22)=0,"",SUM(Quantity!O22:Z22))} -> 14 | L21: {=IF(SUM(CA!O22:Z22)=0,"",SUM(CA!O22:Z22))} -> 10902.9 | M21: {=IF(SUM(Quantity!C22:N22)=0,"",SUM(Quantity!C22:N22))} -> 1 | N21: {=IF(SUM(CA!C22:N22)=0,"",SUM(CA!C22:N22))} -> 400
B22: {=Quantity!B23} -> [ADI016-500] ADIAVET™ MYCO AV FAST TIME | C22: {=Quantity!O23} -> 0 | D22: {=CA!O23} -> 0 | E22: {=Quantity!C23} -> 0 | F22: {=CA!C23} -> 0 | G22: {=SUMIFS(Quantity!$C23:$AH23,Quantity!$C$7:$AH$7,H$6,Quantity!$C$8:$AH$8,TRUE)} -> 0 | H22: {=SUMIFS(CA!$C23:$AQ23,CA!$C$7:$AQ$7,H$6,CA!$C$8:$AQ$8,TRUE)} -> 0 | I22: {=SUMIFS(Quantity!$C23:$AH23,Quantity!$C$7:$AH$7,J$6,Quantity!$C$8:$AH$8,TRUE)} -> 0 | J22: {=SUMIFS(CA!$C23:$AQ23,CA!$C$7:$AQ$7,J$6,CA!$C$8:$AQ$8,TRUE)} -> 0 | K22: {=IF(SUM(Quantity!O23:Z23)=0,"",SUM(Quantity!O23:Z23))} | L22: {=IF(SUM(CA!O23:Z23)=0,"",SUM(CA!O23:Z23))} | M22: {=IF(SUM(Quantity!C23:N23)=0,"",SUM(Quantity!C23:N23))} | N22: {=IF(SUM(CA!C23:N23)=0,"",SUM(CA!C23:N23))}
B23: {=Quantity!B24} -> [ADI033-100] ADIAVET™ APP REAL TIME | C23: {=Quantity!O24} -> 0 | D23: {=CA!O24} -> 0 | E23: {=Quantity!C24} -> 0 | F23: {=CA!C24} -> 0 | G23: {=SUMIFS(Quantity!$C24:$AH24,Quantity!$C$7:$AH$7,H$6,Quantity!$C$8:$AH$8,TRUE)} -> 0 | H23: {=SUMIFS(CA!$C24:$AQ24,CA!$C$7:$AQ$7,H$6,CA!$C$8:$AQ$8,TRUE)} -> 0 | I23: {=SUMIFS(Quantity!$C24:$AH24,Quantity!$C$7:$AH$7,J$6,Quantity!$C$8:$AH$8,TRUE)} -> 0 | J23: {=SUMIFS(CA!$C24:$AQ24,CA!$C$7:$AQ$7,J$6,CA!$C$8:$AQ$8,TRUE)} -> 0 | K23: {=IF(SUM(Quantity!O24:Z24)=0,"",SUM(Quantity!O24:Z24))} -> 1 | L23: {=IF(SUM(CA!O24:Z24)=0,"",SUM(CA!O24:Z24))} -> 403 | M23: {=IF(SUM(Quantity!C24:N24)=0,"",SUM(Quantity!C24:N24))} -> 1 | N23: {=IF(SUM(CA!C24:N24)=0,"",SUM(CA!C24:N24))} -> 743.5
B24: {=Quantity!B25} -> [ADI045-100] ADIAVET™ PARATB REAL TIME | C24: {=Quantity!O25} -> 7 | D24: {=CA!O25} -> 2440.2 | E24: {=Quantity!C25} -> 8 | F24: {=CA!C25} -> 3140.4 | G24: {=SUMIFS(Quantity!$C25:$AH25,Quantity!$C$7:$AH$7,H$6,Quantity!$C$8:$AH$8,TRUE)} -> 0 | H24: {=SUMIFS(CA!$C25:$AQ25,CA!$C$7:$AQ$7,H$6,CA!$C$8:$AQ$8,TRUE)} -> 0 | I24: {=SUMIFS(Quantity!$C25:$AH25,Quantity!$C$7:$AH$7,J$6,Quantity!$C$8:$AH$8,TRUE)} -> 0 | J24: {=SUMIFS(CA!$C25:$AQ25,CA!$C$7:$AQ$7,J$6,CA!$C$8:$AQ$8,TRUE)} -> 0 | K24: {=IF(SUM(Quantity!O25:Z25)=0,"",SUM(Quantity!O25:Z25))} -> 24 | L24: {=IF(SUM(CA!O25:Z25)=0,"",SUM(CA!O25:Z25))} -> 10301.7 | M24: {=IF(SUM(Quantity!C25:N25)=0,"",SUM(Quantity!C25:N25))} -> 37 | N24: {=IF(SUM(CA!C25:N25)=0,"",SUM(CA!C25:N25))} -> 14662.2
B25: {=Quantity!B26} -> [ADI072-100] ADIAVET™ PRV REAL TIME | C25: {=Quantity!O26} -> 0 | D25: {=CA!O26} -> 0 | E25: {=Quantity!C26} -> 0 | F25: {=CA!C26} -> 0 | G25: {=SUMIFS(Quantity!$C26:$AH26,Quantity!$C$7:$AH$7,H$6,Quantity!$C$8:$AH$8,TRUE)} -> 0 | H25: {=SUMIFS(CA!$C26:$AQ26,CA!$C$7:$AQ$7,H$6,CA!$C$8:$AQ$8,TRUE)} -> 0 | I25: {=SUMIFS(Quantity!$C26:$AH26,Quantity!$C$7:$AH$7,J$6,Quantity!$C$8:$AH$8,TRUE)} -> 0 | J25: {=SUMIFS(CA!$C26:$AQ26,CA!$C$7:$AQ$7,J$6,CA!$C$8:$AQ$8,TRUE)} -> 0 | K25: {=IF(SUM(Quantity!O26:Z26)=0,"",SUM(Quantity!O26:Z26))} -> 1 | L25: {=IF(SUM(CA!O26:Z26)=0,"",SUM(CA!O26:Z26))} -> 750 | M25: {=IF(SUM(Quantity!C26:N26)=0,"",SUM(Quantity!C26:N26))} | N25: {=IF(SUM(CA!C26:N26)=0,"",SUM(CA!C26:N26))}
B26: {=Quantity!B27} -> [ADI105-100] ADIAVET™ BVDV REAL TIME | C26: {=Quantity!O27} -> 0 | D26: {=CA!O27} -> 0 | E26: {=Quantity!C27} -> 0 | F26: {=CA!C27} -> 0 | G26: {=SUMIFS(Quantity!$C27:$AH27,Quantity!$C$7:$AH$7,H$6,Quantity!$C$8:$AH$8,TRUE)} -> 0 | H26: {=SUMIFS(CA!$C27:$AQ27,CA!$C$7:$AQ$7,H$6,CA!$C$8:$AQ$8,TRUE)} -> 0 | I26: {=SUMIFS(Quantity!$C27:$AH27,Quantity!$C$7:$AH$7,J$6,Quantity!$C$8:$AH$8,TRUE)} -> 0 | J26: {=SUMIFS(CA!$C27:$AQ27,CA!$C$7:$AQ$7,J$6,CA!$C$8:$AQ$8,TRUE)} -> 0 | K26: {=IF(SUM(Quantity!O27:Z27)=0,"",SUM(Quantity!O27:Z27))} -> 2 | L26: {=IF(SUM(CA!O27:Z27)=0,"",SUM(CA!O27:Z27))} -> 900 | M26: {=IF(SUM(Quantity!C27:N27)=0,"",SUM(Quantity!C27:N27))} -> 12 | N26: {=IF(SUM(CA!C27:N27)=0,"",SUM(CA!C27:N27))} -> 9779.3
B27: {=Quantity!B28} -> [ADI105-500] ADIAVET™ BVDV REAL TIME | C27: {=Quantity!O28} -> 7 | D27: {=CA!O28} -> 5950 | E27: {=Quantity!C28} -> 9 | F27: {=CA!C28} -> 7650 | G27: {=SUMIFS(Quantity!$C28:$AH28,Quantity!$C$7:$AH$7,H$6,Quantity!$C$8:$AH$8,TRUE)} -> 0 | H27: {=SUMIFS(CA!$C28:$AQ28,CA!$C$7:$AQ$7,H$6,CA!$C$8:$AQ$8,TRUE)} -> 0 | I27: {=SUMIFS(Quantity!$C28:$AH28,Quantity!$C$7:$AH$7,J$6,Quantity!$C$8:$AH$8,TRUE)} -> 0 | J27: {=SUMIFS(CA!$C28:$AQ28,CA!$C$7:$AQ$7,J$6,CA!$C$8:$AQ$8,TRUE)} -> 0 | K27: {=IF(SUM(Quantity!O28:Z28)=0,"",SUM(Quantity!O28:Z28))} -> 102 | L27: {=IF(SUM(CA!O28:Z28)=0,"",SUM(CA!O28:Z28))} -> 86700 | M27: {=IF(SUM(Quantity!C28:N28)=0,"",SUM(Quantity!C28:N28))} -> 107 | N27: {=IF(SUM(CA!C28:N28)=0,"",SUM(CA!C28:N28))} -> 90950
B28: {=Quantity!B29} -> [ADI106-100] ADIAVET BVDV FAST TIME 100R (historique) | C28: {=Quantity!O29} -> 0 | D28: {=CA!O29} -> 0 | E28: {=Quantity!C29} -> 0 | F28: {=CA!C29} -> 0 | G28: {=SUMIFS(Quantity!$C29:$AH29,Quantity!$C$7:$AH$7,H$6,Quantity!$C$8:$AH$8,TRUE)} -> 0 | H28: {=SUMIFS(CA!$C29:$AQ29,CA!$C$7:$AQ$7,H$6,CA!$C$8:$AQ$8,TRUE)} -> 0 | I28: {=SUMIFS(Quantity!$C29:$AH29,Quantity!$C$7:$AH$7,J$6,Quantity!$C$8:$AH$8,TRUE)} -> 0 | J28: {=SUMIFS(CA!$C29:$AQ29,CA!$C$7:$AQ$7,J$6,CA!$C$8:$AQ$8,TRUE)} -> 0 | K28: {=IF(SUM(Quantity!O29:Z29)=0,"",SUM(Quantity!O29:Z29))} | L28: {=IF(SUM(CA!O29:Z29)=0,"",SUM(CA!O29:Z29))} | M28: {=IF(SUM(Quantity!C29:N29)=0,"",SUM(Quantity!C29:N29))} | N28: {=IF(SUM(CA!C29:N29)=0,"",SUM(CA!C29:N29))}
B29: {=Quantity!B30} -> [ADI122-100] ADIAVET™ SALMO FAST TIME | C29: {=Quantity!O30} -> 0 | D29: {=CA!O30} -> 0 | E29: {=Quantity!C30} -> 0 | F29: {=CA!C30} -> 0 | G29: {=SUMIFS(Quantity!$C30:$AH30,Quantity!$C$7:$AH$7,H$6,Quantity!$C$8:$AH$8,TRUE)} -> 0 | H29: {=SUMIFS(CA!$C30:$AQ30,CA!$C$7:$AQ$7,H$6,CA!$C$8:$AQ$8,TRUE)} -> 0 | I29: {=SUMIFS(Quantity!$C30:$AH30,Quantity!$C$7:$AH$7,J$6,Quantity!$C$8:$AH$8,TRUE)} -> 0 | J29: {=SUMIFS(CA!$C30:$AQ30,CA!$C$7:$AQ$7,J$6,CA!$C$8:$AQ$8,TRUE)} -> 0 | K29: {=IF(SUM(Quantity!O30:Z30)=0,"",SUM(Quantity!O30:Z30))} | L29: {=IF(SUM(CA!O30:Z30)=0,"",SUM(CA!O30:Z30))} | M29: {=IF(SUM(Quantity!C30:N30)=0,"",SUM(Quantity!C30:N30))} | N29: {=IF(SUM(CA!C30:N30)=0,"",SUM(CA!C30:N30))}
... B537: {=Quantity!B538} -> 0 | C537: {=Quantity!O538} -> 0 | D537: {=CA!O538} -> 0 | E537: {=Quantity!C538} -> 0 | F537: {=CA!C538} -> 0 | G537: {=SUMIFS(Quantity!$C538:$AH538,Quantity!$C$7:$AH$7,H$6,Quantity!$C$8:$AH$8,TRUE)} -> 0 | H537: {=SUMIFS(CA!$C538:$AQ538,CA!$C$7:$AQ$7,H$6,CA!$C$8:$AQ$8,TRUE)} -> 0 | I537: {=SUMIFS(Quantity!$C538:$AH538,Quantity!$C$7:$AH$7,J$6,Quantity!$C$8:$AH$8,TRUE)} -> 0 | J537: {=SUMIFS(CA!$C538:$AQ538,CA!$C$7:$AQ$7,J$6,CA!$C$8:$AQ$8,TRUE)} -> 0 | K537: {=IF(SUM(Quantity!O538:Z538)=0,"",SUM(Quantity!O538:Z538))} | L537: {=IF(SUM(CA!O538:Z538)=0,"",SUM(CA!O538:Z538))} | M537: {=IF(SUM(Quantity!C538:N538)=0,"",SUM(Quantity!C538:N538))} | N537: {=IF(SUM(CA!C538:N538)=0,"",SUM(CA!C538:N538))}
B538: {=Quantity!B539} -> 0 | C538: {=Quantity!O539} -> 0 | D538: {=CA!O539} -> 0 | E538: {=Quantity!C539} -> 0 | F538: {=CA!C539} -> 0 | K538: {=IF(SUM(Quantity!O539:Z539)=0,"",SUM(Quantity!O539:Z539))} | L538: {=IF(SUM(CA!O539:Z539)=0,"",SUM(CA!O539:Z539))} | M538: {=IF(SUM(Quantity!C539:N539)=0,"",SUM(Quantity!C539:N539))} | N538: {=IF(SUM(CA!C539:N539)=0,"",SUM(CA!C539:N539))}

Sheet Categories
G2: ADIAVET
G3: ADIALYO | I3: formule data : IF(ODOO.FILTER.VALUE("Start Date (M/DD/YYYY)")="",today(),ODOO.FILTER.VALUE("Start Date (M/DD/YYYY)"))
G4: PCR
G5: ADIAPURE
G6: ADIAMAG
G7: EXT
G8: Total BioMol SA
G9: SARS Cov 2
G10: Total PCR
G11: Moab
G12: Elisa
G13: PoC
G14: Total immuno
G15: Total Bio X
G16: Total Bio X

Sheet CA
B1: pivot # | C1: 4
B2: measure 1 | C2: balance
B3: Date to begin | C3: {=IF(Dashboard!C2="",TODAY(),Dashboard!C2)} -> 01/31/2026
B4: group_by : | C4: #product_id
C5: 0 | D5: 1 | E5: 2 | F5: 3 | G5: 4 | H5: 5 | I5: 6 | J5: 7 | K5: 8 | L5: 9 | M5: 10 | N5: 11 | O5: 12 | P5: 13 | Q5: 14 | R5: 15 | S5: 16 | T5: 17 | U5: 18 | V5: 19 | W5: 20 | X5: 21 | Y5: 22 | Z5: 23 | AA5: 24 | AB5: 25 | AC5: 26 | AD5: 27 | AE5: 28 | AF5: 29 | AG5: 30 | AH5: 31
B6: Date | C6: {=TEXT(MONTH(EDATE($C$3,-C5)),"00")&"/"&YEAR(EDATE($C$3,-C5))} -> #VALUE! | D6: {=TEXT(MONTH(EDATE($C$3,-D5)),"00")&"/"&YEAR(EDATE($C$3,-D5))} -> #VALUE! | E6: {=TEXT(MONTH(EDATE($C$3,-E5)),"00")&"/"&YEAR(EDATE($C$3,-E5))} -> #VALUE! | F6: {=TEXT(MONTH(EDATE($C$3,-F5)),"00")&"/"&YEAR(EDATE($C$3,-F5))} -> #VALUE! | G6: {=TEXT(MONTH(EDATE($C$3,-G5)),"00")&"/"&YEAR(EDATE($C$3,-G5))} -> #VALUE! | H6: {=TEXT(MONTH(EDATE($C$3,-H5)),"00")&"/"&YEAR(EDATE($C$3,-H5))} -> #VALUE! | I6: {=TEXT(MONTH(EDATE($C$3,-I5)),"00")&"/"&YEAR(EDATE($C$3,-I5))} -> #VALUE! | J6: {=TEXT(MONTH(EDATE($C$3,-J5)),"00")&"/"&YEAR(EDATE($C$3,-J5))} -> #VALUE! | ... AH6: {=TEXT(MONTH(EDATE($C$3,-AH5)),"00")&"/"&YEAR(EDATE($C$3,-AH5))} -> #VALUE!
B7: Previous start of fiscal year | C7: {="09/"&YEAR(EDATE($C$3,-C5-8))} -> #VALUE! | D7: {="09/"&YEAR(EDATE($C$3,-D5-8))} -> #VALUE! | E7: {="09/"&YEAR(EDATE($C$3,-E5-8))} -> #VALUE! | F7: {="09/"&YEAR(EDATE($C$3,-F5-8))} -> #VALUE! | G7: {="09/"&YEAR(EDATE($C$3,-G5-8))} -> #VALUE! | H7: {="09/"&YEAR(EDATE($C$3,-H5-8))} -> #VALUE! | I7: {="09/"&YEAR(EDATE($C$3,-I5-8))} -> #VALUE! | J7: {="09/"&YEAR(EDATE($C$3,-J5-8))} -> #VALUE! | ... AH7: {="09/"&YEAR(EDATE($C$3,-AH5-8))} -> #VALUE!
B8: Taken in this fiscal year | C8: {=IF(MONTH(EDATE($C$3,-$C$5+4))-MONTH(EDATE($C$3,-C5+4))>=0,TRUE,FALSE)} -> #VALUE! | D8: {=IF(MONTH(EDATE($C$3,-$C$5+4))-MONTH(EDATE($C$3,-D5+4))>=0,TRUE,FALSE)} -> #VALUE! | E8: {=IF(MONTH(EDATE($C$3,-$C$5+4))-MONTH(EDATE($C$3,-E5+4))>=0,TRUE,FALSE)} -> #VALUE! | F8: {=IF(MONTH(EDATE($C$3,-$C$5+4))-MONTH(EDATE($C$3,-F5+4))>=0,TRUE,FALSE)} -> #VALUE! | G8: {=IF(MONTH(EDATE($C$3,-$C$5+4))-MONTH(EDATE($C$3,-G5+4))>=0,TRUE,FALSE)} -> #VALUE! | H8: {=IF(MONTH(EDATE($C$3,-$C$5+4))-MONTH(EDATE($C$3,-H5+4))>=0,TRUE,FALSE)} -> #VALUE! | I8: {=IF(MONTH(EDATE($C$3,-$C$5+4))-MONTH(EDATE($C$3,-I5+4))>=0,TRUE,FALSE)} -> #VALUE! | J8: {=IF(MONTH(EDATE($C$3,-$C$5+4))-MONTH(EDATE($C$3,-J5+4))>=0,TRUE,FALSE)} -> #VALUE! | ... AH8: {=IF(MONTH(EDATE($C$3,-$C$5+4))-MONTH(EDATE($C$3,-AH5+4))>=0,TRUE,FALSE)} -> #VALUE!
C9: {=$C$2} -> balance | D9: {=$C$2} -> balance | E9: {=$C$2} -> balance | F9: {=$C$2} -> balance | G9: {=$C$2} -> balance | H9: {=$C$2} -> balance | I9: {=$C$2} -> balance | J9: {=$C$2} -> balance | ... AI9: {=$C$2} -> balance
A10: 1 | B10: [ADPREP-100] ADIAPREP™ 100 | C10: 0 | D10: 185 | E10: 0 | F10: 0 | G10: 0 | H10: 0 | I10: 0 | J10: 0 | K10: 0 | L10: 0 | M10: 0 | N10: 0 | O10: 0 | P10: 0 | Q10: 0 | R10: 0 | S10: 0 | T10: 0 | U10: 0 | V10: 0 | W10: 0 | X10: 0 | Y10: 0 | Z10: 0 | AA10: 0 | AB10: 0 | AC10: 0 | AD10: 0 | AE10: 0 | AF10: 0 | AG10: 0 | AH10: 0 | AI10: {=SUM(C10:AH10)} -> 185
A11: 2 | B11: [#417996] ADIAVET™ MYCO AV REAL TIME | C11: 0 | D11: 0 | E11: 0 | F11: 0 | G11: 0 | H11: 0 | I11: 0 | J11: 0 | K11: 0 | L11: 0 | M11: 0 | N11: 0 | O11: 0 | P11: 0 | Q11: 0 | R11: 0 | S11: 0 | T11: 0 | U11: 0 | V11: 0 | W11: 0 | X11: 0 | Y11: 0 | Z11: 0 | AA11: 0 | AB11: 0 | AC11: 0 | AD11: 0 | AE11: 0 | AF11: 0 | AG11: 0 | AH11: 0 | AI11: {=SUM(C11:AH11)} -> 0
A12: 3 | B12: [#418020] ADIAVET™ LAW REAL TIME | C12: 0 | D12: 0 | E12: 0 | F12: 0 | G12: 0 | H12: 0 | I12: 0 | J12: 0 | K12: 0 | L12: 0 | M12: 0 | N12: 0 | O12: 0 | P12: 2016.6 | Q12: 0 | R12: 2016.6 | S12: 0 | T12: 1008.3 | U12: 1008.3 | V12: 0 | W12: 0 | X12: 0 | Y12: 0 | Z12: 0 | AA12: 900 | AB12: 1800 | AC12: 0 | AD12: 0 | AE12: 0 | AF12: 0 | AG12: 0 | AH12: 1800 | AI12: {=SUM(C12:AH12)} -> 10549.8
A13: 4 | B13: [#418021] ADIAVET™ BRACHY REAL TIME | C13: 0 | D13: 949.5 | E13: 949.5 | F13: 0 | G13: 0 | H13: 0 | I13: 0 | J13: 0 | K13: 0 | L13: 0 | M13: 0 | N13: 0 | O13: 0 | P13: 0 | Q13: 0 | R13: 0 | S13: 0 | T13: 0 | U13: 0 | V13: 0 | W13: 0 | X13: 0 | Y13: 983.7 | Z13: 0 | AA13: 0 | AB13: 0 | AC13: 0 | AD13: 0 | AE13: 0 | AF13: 0 | AG13: 0 | AH13: 0 | AI13: {=SUM(C13:AH13)} -> 2882.7
A14: 5 | B14: [#418022] ADIAVET™ M.HYOP REAL TIME | C14: 0 | D14: 0 | E14: 0 | F14: 0 | G14: 0 | H14: 0 | I14: 0 | J14: 0 | K14: 0 | L14: 0 | M14: 0 | N14: 0 | O14: 0 | P14: 0 | Q14: 0 | R14: 0 | S14: 0 | T14: 0 | U14: 0 | V14: 0 | W14: 0 | X14: 0 | Y14: 0 | Z14: 927 | AA14: 0 | AB14: 0 | AC14: 0 | AD14: 0 | AE14: 0 | AF14: 0 | AG14: 0 | AH14: 0 | AI14: {=SUM(C14:AH14)} -> 927
A15: 6 | B15: [#418023] ADIAVET™ NEOSPORA REAL TIME | C15: 0 | D15: 0 | E15: 0 | F15: 0 | G15: 0 | H15: 0 | I15: 0 | J15: 0 | K15: 560 | L15: 0 | M15: 0 | N15: 0 | O15: 0 | P15: 560 | Q15: 0 | R15: 0 | S15: 0 | T15: 0 | U15: 0 | V15: 0 | W15: 280 | X15: 0 | Y15: 0 | Z15: 0 | AA15: 0 | AB15: 0 | AC15: 280 | AD15: 0 | AE15: 280 | AF15: 0 | AG15: 0 | AH15: 280 | AI15: {=SUM(C15:AH15)} -> 2240
A16: 7 | B16: [#418024] ADIAVET™ CHLAM.A. REAL TIME | C16: 0 | D16: 0 | E16: 0 | F16: 0 | G16: 280 | H16: 0 | I16: 0 | J16: 0 | K16: 0 | L16: 0 | M16: 280 | N16: 0 | O16: 0 | P16: 560 | Q16: 0 | R16: 280 | S16: 0 | T16: 0 | U16: 280 | V16: 0 | W16: 0 | X16: 0 | Y16: 0 | Z16: 0 | AA16: 280 | AB16: 0 | AC16: 560 | AD16: 0 | AE16: 0 | AF16: 0 | AG16: 280 | AH16: 0 | AI16: {=SUM(C16:AH16)} -> 2800
A17: 8 | B17: [#418026] ADIAVET™ LEPTO REAL TIME | C17: 2200 | D17: 2200 | E17: 550 | F17: 0 | G17: 2200 | H17: 0 | I17: 0 | J17: 0 | K17: 5300 | L17: 0 | M17: 3850 | N17: 550 | O17: 2200 | P17: 2200 | Q17: 0 | R17: 0 | S17: 2200 | T17: 0 | U17: 1100 | V17: 0 | W17: 2200 | X17: 2200 | Y17: 0 | Z17: 0 | AA17: 2750 | AB17: 0 | AC17: 2750 | AD17: 0 | AE17: 2200 | AF17: 0 | AG17: 2200 | AH17: 0 | AI17: {=SUM(C17:AH17)} -> 38850
A18: 9 | B18: [#418027] ADIAVET™ TOXO REAL TIME | C18: 0 | D18: 0 | E18: 0 | F18: 0 | G18: 0 | H18: 0 | I18: 0 | J18: 0 | K18: 0 | L18: 0 | M18: 0 | N18: 0 | O18: 0 | P18: 0 | Q18: 0 | R18: 0 | S18: 0 | T18: 0 | U18: 0 | V18: 0 | W18: 0 | X18: 0 | Y18: 0 | Z18: 0 | AA18: 0 | AB18: 0 | AC18: 0 | AD18: 0 | AE18: 0 | AF18: 0 | AG18: 0 | AH18: 0 | AI18: {=SUM(C18:AH18)} -> 0
A19: 10 | B19: [#418028] ADIAVET™ ANA PHA REAL TIME | C19: 1050 | D19: 1750 | E19: 1750 | F19: 700 | G19: 3150 | H19: 1050 | I19: 2800 | J19: 1050 | K19: 0 | L19: 1400 | M19: 0 | N19: 2200 | O19: 350 | P19: 700 | Q19: 700 | R19: 2450 | S19: 350 | T19: 2100 | U19: 350 | V19: 1050 | W19: 0 | X19: 1050 | Y19: 0 | Z19: 1050 | AA19: 1400 | AB19: 0 | AC19: 1050 | AD19: 0 | AE19: 1750 | AF19: 2100 | AG19: 700 | AH19: 1050 | AI19: {=SUM(C19:AH19)} -> 35100
A20: 11 | B20: [ADC04SQ01] Adiacontrol Quantified Extraction Positive Control Paratb Faeces | C20: 0 | D20: 0 | E20: 0 | F20: 0 | G20: 0 | H20: 0 | I20: 0 | J20: 0 | K20: 0 | L20: 0 | M20: 0 | N20: 0 | O20: 0 | P20: 0 | Q20: 0 | R20: 0 | S20: 0 | T20: 0 | U20: 0 | V20: 0 | W20: 0 | X20: 0 | Y20: 0 | Z20: 0 | AA20: 0 | AB20: 0 | AC20: 0 | AD20: 0 | AE20: 0 | AF20: 0 | AG20: 0 | AH20: 0 | AI20: {=SUM(C20:AH20)} -> 0
A21: 12 | B21: [ADC10S02] Adiacontrol Extraction Positive Control BVDV EAR | C21: 0 | D21: 0 | E21: 0 | F21: 0 | G21: 0 | H21: 0 | I21: 0 | J21: 0 | K21: 0 | L21: 0 | M21: 0 | N21: 0 | O21: 0 | P21: 0 | Q21: 0 | R21: 0 | S21: 0 | T21: 0 | U21: 0 | V21: 0 | W21: 0 | X21: 0 | Y21: 0 | Z21: 0 | AA21: 0 | AB21: 0 | AC21: 0 | AD21: 0 | AE21: 0 | AF21: 0 | AG21: 0 | AH21: 0 | AI21: {=SUM(C21:AH21)} -> 0
... A91: 82 | B91: [NIDC22PL-20] Easy prep BVD | C91: 0 | D91: 0 | E91: 0 | F91: 0 | G91: 0 | H91: 0 | I91: 0 | J91: 0 | K91: 0 | L91: 0 | M91: 0 | N91: 0 | O91: 0 | P91: 0 | Q91: 0 | R91: 0 | S91: 0 | T91: 0 | U91: 0 | V91: 0 | W91: 0 | X91: 0 | Y91: 0 | Z91: 0 | AA91: 0 | AB91: 0 | AC91: 0 | AD91: 0 | AE91: 0 | AF91: 600 | AG91: 1800 | AH91: 0 | AI91: {=SUM(C91:AH91)} -> 2400
A92: 83 | C92: 0 | D92: 0 | E92: 0 | F92: 0 | G92: 0 | H92: 0 | I92: 0 | J92: 0 | K92: 0 | L92: 0 | M92: 0 | N92: 0 | O92: 0 | P92: 0 | Q92: 0 | R92: 0 | S92: 0 | T92: 0 | U92: 0 | V92: 0 | W92: 0 | X92: 0 | Y92: 0 | Z92: 0 | AA92: 0 | AB92: 0 | AC92: 0 | AD92: 0 | AE92: 0 | AF92: 0 | AG92: 0 | AH92: 0 | AI92: {=SUM(C92:AH92)} -> 0
A93: 84 | C93: 0 | D93: 0 | E93: 0 | F93: 0 | G93: 0 | H93: 0 | I93: 0 | J93: 0 | K93: 0 | L93: 0 | M93: 0 | N93: 0 | O93: 0 | P93: 0 | Q93: 0 | R93: 0 | S93: 0 | T93: 0 | U93: 0 | V93: 0 | W93: 0 | X93: 0 | Y93: 0 | Z93: 0 | AA93: 0 | AB93: 0 | AC93: 0 | AD93: 0 | AE93: 0 | AF93: 0 | AG93: 0 | AH93: 0 | AI93: {=SUM(C93:AH93)} -> 0
A94: 85 | C94: 0 | D94: 0 | E94: 0 | F94: 0 | G94: 0 | H94: 0 | I94: 0 | J94: 0 | K94: 0 | L94: 0 | M94: 0 | N94: 0 | O94: 0 | P94: 0 | Q94: 0 | R94: 0 | S94: 0 | T94: 0 | U94: 0 | V94: 0 | W94: 0 | X94: 0 | Y94: 0 | Z94: 0 | AA94: 0 | AB94: 0 | AC94: 0 | AD94: 0 | AE94: 0 | AF94: 0 | AG94: 0 | AH94: 0 | AI94: {=SUM(C94:AH94)} -> 0
A95: 86 | C95: 0 | D95: 0 | E95: 0 | F95: 0 | G95: 0 | H95: 0 | I95: 0 | J95: 0 | K95: 0 | L95: 0 | M95: 0 | N95: 0 | O95: 0 | P95: 0 | Q95: 0 | R95: 0 | S95: 0 | T95: 0 | U95: 0 | V95: 0 | W95: 0 | X95: 0 | Y95: 0 | Z95: 0 | AA95: 0 | AB95: 0 | AC95: 0 | AD95: 0 | AE95: 0 | AF95: 0 | AG95: 0 | AH95: 0 | AI95: {=SUM(C95:AH95)} -> 0
A96: 87 | C96: 0 | D96: 0 | E96: 0 | F96: 0 | G96: 0 | H96: 0 | I96: 0 | J96: 0 | K96: 0 | L96: 0 | M96: 0 | N96: 0 | O96: 0 | P96: 0 | Q96: 0 | R96: 0 | S96: 0 | T96: 0 | U96: 0 | V96: 0 | W96: 0 | X96: 0 | Y96: 0 | Z96: 0 | AA96: 0 | AB96: 0 | AC96: 0 | AD96: 0 | AE96: 0 | AF96: 0 | AG96: 0 | AH96: 0 | AI96: {=SUM(C96:AH96)} -> 0
A97: 88 | C97: 0 | D97: 0 | E97: 0 | F97: 0 | G97: 0 | H97: 0 | I97: 0 | J97: 0 | K97: 0 | L97: 0 | M97: 0 | N97: 0 | O97: 0 | P97: 0 | Q97: 0 | R97: 0 | S97: 0 | T97: 0 | U97: 0 | V97: 0 | W97: 0 | X97: 0 | Y97: 0 | Z97: 0 | AA97: 0 | AB97: 0 | AC97: 0 | AD97: 0 | AE97: 0 | AF97: 0 | AG97: 0 | AH97: 0 | AI97: {=SUM(C97:AH97)} -> 0
A98: 89 | C98: 0 | D98: 0 | E98: 0 | F98: 0 | G98: 0 | H98: 0 | I98: 0 | J98: 0 | K98: 0 | L98: 0 | M98: 0 | N98: 0 | O98: 0 | P98: 0 | Q98: 0 | R98: 0 | S98: 0 | T98: 0 | U98: 0 | V98: 0 | W98: 0 | X98: 0 | Y98: 0 | Z98: 0 | AA98: 0 | AB98: 0 | AC98: 0 | AD98: 0 | AE98: 0 | AF98: 0 | AG98: 0 | AH98: 0 | AI98: {=SUM(C98:AH98)} -> 0
A99: 90 | C99: 0 | D99: 0 | E99: 0 | F99: 0 | G99: 0 | H99: 0 | I99: 0 | J99: 0 | K99: 0 | L99: 0 | M99: 0 | N99: 0 | O99: 0 | P99: 0 | Q99: 0 | R99: 0 | S99: 0 | T99: 0 | U99: 0 | V99: 0 | W99: 0 | X99: 0 | Y99: 0 | Z99: 0 | AA99: 0 | AB99: 0 | AC99: 0 | AD99: 0 | AE99: 0 | AF99: 0 | AG99: 0 | AH99: 0 | AI99: {=SUM(C99:AH99)} -> 0
A100: 91 | C100: 0 | D100: 0 | E100: 0 | F100: 0 | G100: 0 | H100: 0 | I100: 0 | J100: 0 | K100: 0 | L100: 0 | M100: 0 | N100: 0 | O100: 0 | P100: 0 | Q100: 0 | R100: 0 | S100: 0 | T100: 0 | U100: 0 | V100: 0 | W100: 0 | X100: 0 | Y100: 0 | Z100: 0 | AA100: 0 | AB100: 0 | AC100: 0 | AD100: 0 | AE100: 0 | AF100: 0 | AG100: 0 | AH100: 0 | AI100: {=SUM(C100:AH100)} -> 0
A101: 92 | C101: 0 | D101: 0 | E101: 0 | F101: 0 | G101: 0 | H101: 0 | I101: 0 | J101: 0 | K101: 0 | L101: 0 | M101: 0 | N101: 0 | O101: 0 | P101: 0 | Q101: 0 | R101: 0 | S101: 0 | T101: 0 | U101: 0 | V101: 0 | W101: 0 | X101: 0 | Y101: 0 | Z101: 0 | AA101: 0 | AB101: 0 | AC101: 0 | AD101: 0 | AE101: 0 | AF101: 0 | AG101: 0 | AH101: 0 | AI101: {=SUM(C101:AH101)} -> 0
A102: 93 | C102: 0 | D102: 0 | E102: 0 | F102: 0 | G102: 0 | H102: 0 | I102: 0 | J102: 0 | K102: 0 | L102: 0 | M102: 0 | N102: 0 | O102: 0 | P102: 0 | Q102: 0 | R102: 0 | S102: 0 | T102: 0 | U102: 0 | V102: 0 | W102: 0 | X102: 0 | Y102: 0 | Z102: 0 | AA102: 0 | AB102: 0 | AC102: 0 | AD102: 0 | AE102: 0 | AF102: 0 | AG102: 0 | AH102: 0 | AI102: {=SUM(C102:AH102)} -> 0
A103: 94 | C103: 0 | D103: 0 | E103: 0 | F103: 0 | G103: 0 | H103: 0 | I103: 0 | J103: 0 | K103: 0 | L103: 0 | M103: 0 | N103: 0 | O103: 0 | P103: 0 | Q103: 0 | R103: 0 | S103: 0 | T103: 0 | U103: 0 | V103: 0 | W103: 0 | X103: 0 | Y103: 0 | Z103: 0 | AA103: 0 | AB103: 0 | AC103: 0 | AD103: 0 | AE103: 0 | AF103: 0 | AG103: 0 | AH103: 0 | AI103: {=SUM(C103:AH103)} -> 0
... A551: 542 | C551: 0 | D551: 0 | E551: 0 | F551: 0 | G551: 0 | H551: 0 | I551: 0 | J551: 0 | K551: 0 | L551: 0 | M551: 0 | N551: 0 | O551: 0 | P551: 0 | Q551: 0 | R551: 0 | S551: 0 | T551: 0 | U551: 0 | V551: 0 | W551: 0 | X551: 0 | Y551: 0 | Z551: 0 | AA551: 0 | AB551: 0 | AC551: 0 | AD551: 0 | AE551: 0 | AF551: 0 | AG551: 0 | AH551: 0 | AI551: {=SUM(C551:AH551)} -> 0

Sheet Quantity
B1: pivot # | C1: 4
B2: measure 1 | C2: quantity
B3: Date to begin | C3: {=IF(Dashboard!C2="",TODAY(),Dashboard!C2)} -> 01/31/2026
B4: group_by : | C4: #product_id
C5: 0 | D5: 1 | E5: 2 | F5: 3 | G5: 4 | H5: 5 | I5: 6 | J5: 7 | K5: 8 | L5: 9 | M5: 10 | N5: 11 | O5: 12 | P5: 13 | Q5: 14 | R5: 15 | S5: 16 | T5: 17 | U5: 18 | V5: 19 | W5: 20 | X5: 21 | Y5: 22 | Z5: 23 | AA5: 24 | AB5: 25 | AC5: 26 | AD5: 27 | AE5: 28 | AF5: 29 | AG5: 30 | AH5: 31
B6: Date | C6: {=TEXT(MONTH(EDATE($C$3,-C5)),"00")&"/"&YEAR(EDATE($C$3,-C5))} -> #VALUE! | D6: {=TEXT(MONTH(EDATE($C$3,-D5)),"00")&"/"&YEAR(EDATE($C$3,-D5))} -> #VALUE! | E6: {=TEXT(MONTH(EDATE($C$3,-E5)),"00")&"/"&YEAR(EDATE($C$3,-E5))} -> #VALUE! | F6: {=TEXT(MONTH(EDATE($C$3,-F5)),"00")&"/"&YEAR(EDATE($C$3,-F5))} -> #VALUE! | G6: {=TEXT(MONTH(EDATE($C$3,-G5)),"00")&"/"&YEAR(EDATE($C$3,-G5))} -> #VALUE! | H6: {=TEXT(MONTH(EDATE($C$3,-H5)),"00")&"/"&YEAR(EDATE($C$3,-H5))} -> #VALUE! | I6: {=TEXT(MONTH(EDATE($C$3,-I5)),"00")&"/"&YEAR(EDATE($C$3,-I5))} -> #VALUE! | J6: {=TEXT(MONTH(EDATE($C$3,-J5)),"00")&"/"&YEAR(EDATE($C$3,-J5))} -> #VALUE! | ... AH6: {=TEXT(MONTH(EDATE($C$3,-AH5)),"00")&"/"&YEAR(EDATE($C$3,-AH5))} -> #VALUE!
B7: Previous start of fiscal year | C7: {="09/"&YEAR(EDATE($C$3,-C5-8))} -> #VALUE! | D7: {="09/"&YEAR(EDATE($C$3,-D5-8))} -> #VALUE! | E7: {="09/"&YEAR(EDATE($C$3,-E5-8))} -> #VALUE! | F7: {="09/"&YEAR(EDATE($C$3,-F5-8))} -> #VALUE! | G7: {="09/"&YEAR(EDATE($C$3,-G5-8))} -> #VALUE! | H7: {="09/"&YEAR(EDATE($C$3,-H5-8))} -> #VALUE! | I7: {="09/"&YEAR(EDATE($C$3,-I5-8))} -> #VALUE! | J7: {="09/"&YEAR(EDATE($C$3,-J5-8))} -> #VALUE! | ... AH7: {="09/"&YEAR(EDATE($C$3,-AH5-8))} -> #VALUE!
B8: Taken in this fiscal year | C8: {=IF(MONTH(EDATE($C$3,-$C$5+4))-MONTH(EDATE($C$3,-C5+4))>=0,TRUE,FALSE)} -> #VALUE! | D8: {=IF(MONTH(EDATE($C$3,-$C$5+4))-MONTH(EDATE($C$3,-D5+4))>=0,TRUE,FALSE)} -> #VALUE! | E8: {=IF(MONTH(EDATE($C$3,-$C$5+4))-MONTH(EDATE($C$3,-E5+4))>=0,TRUE,FALSE)} -> #VALUE! | F8: {=IF(MONTH(EDATE($C$3,-$C$5+4))-MONTH(EDATE($C$3,-F5+4))>=0,TRUE,FALSE)} -> #VALUE! | G8: {=IF(MONTH(EDATE($C$3,-$C$5+4))-MONTH(EDATE($C$3,-G5+4))>=0,TRUE,FALSE)} -> #VALUE! | H8: {=IF(MONTH(EDATE($C$3,-$C$5+4))-MONTH(EDATE($C$3,-H5+4))>=0,TRUE,FALSE)} -> #VALUE! | I8: {=IF(MONTH(EDATE($C$3,-$C$5+4))-MONTH(EDATE($C$3,-I5+4))>=0,TRUE,FALSE)} -> #VALUE! | J8: {=IF(MONTH(EDATE($C$3,-$C$5+4))-MONTH(EDATE($C$3,-J5+4))>=0,TRUE,FALSE)} -> #VALUE! | ... AH8: {=IF(MONTH(EDATE($C$3,-$C$5+4))-MONTH(EDATE($C$3,-AH5+4))>=0,TRUE,FALSE)} -> #VALUE!
C9: {=$C$2} -> quantity | D9: {=$C$2} -> quantity | E9: {=$C$2} -> quantity | F9: {=$C$2} -> quantity | G9: {=$C$2} -> quantity | H9: {=$C$2} -> quantity | I9: {=$C$2} -> quantity | J9: {=$C$2} -> quantity | ... AI9: {=$C$2} -> quantity
A10: 1 | B10: [ADPREP-100] ADIAPREP™ 100 | D10: 1 | AI10: {=SUM(C10:AH10)} -> 1
A11: 2 | B11: [#417996] ADIAVET™ MYCO AV REAL TIME | AI11: {=SUM(C11:AH11)} -> 0
A12: 3 | B12: [#418020] ADIAVET™ LAW REAL TIME | P12: 2 | R12: 2 | T12: 1 | U12: 1 | AA12: 1 | AB12: 2 | AH12: 2 | AI12: {=SUM(C12:AH12)} -> 11
A13: 4 | B13: [#418021] ADIAVET™ BRACHY REAL TIME | D13: 1 | E13: 1 | Y13: 1 | AI13: {=SUM(C13:AH13)} -> 3
A14: 5 | B14: [#418022] ADIAVET™ M.HYOP REAL TIME | Z14: 1 | AI14: {=SUM(C14:AH14)} -> 1
A15: 6 | B15: [#418023] ADIAVET™ NEOSPORA REAL TIME | K15: 2 | P15: 2 | W15: 1 | AC15: 1 | AE15: 1 | AH15: 1 | AI15: {=SUM(C15:AH15)} -> 8
A16: 7 | B16: [#418024] ADIAVET™ CHLAM.A. REAL TIME | G16: 1 | M16: 1 | P16: 2 | R16: 1 | U16: 1 | AA16: 1 | AC16: 2 | AG16: 1 | AI16: {=SUM(C16:AH16)} -> 10
A17: 8 | B17: [#418026] ADIAVET™ LEPTO REAL TIME | C17: 4 | D17: 4 | E17: 1 | G17: 4 | K17: 10 | M17: 7 | N17: 1 | O17: 4 | P17: 4 | S17: 4 | U17: 2 | W17: 4 | X17: 4 | AA17: 5 | AC17: 5 | AE17: 4 | AG17: 4 | AI17: {=SUM(C17:AH17)} -> 71
A18: 9 | B18: [#418027] ADIAVET™ TOXO REAL TIME | AI18: {=SUM(C18:AH18)} -> 0
A19: 10 | B19: [#418028] ADIAVET™ ANA PHA REAL TIME | C19: 3 | D19: 5 | E19: 5 | F19: 2 | G19: 9 | H19: 3 | I19: 8 | J19: 3 | L19: 4 | N19: 4 | O19: 1 | P19: 2 | Q19: 2 | R19: 7 | S19: 1 | T19: 6 | U19: 1 | V19: 3 | X19: 3 | Z19: 3 | AA19: 4 | AC19: 3 | AE19: 5 | AF19: 6 | AG19: 2 | AH19: 3 | AI19: {=SUM(C19:AH19)} -> 98
A20: 11 | B20: [ADC04SQ01] Adiacontrol Quantified Extraction Positive Control Paratb Faeces | F20: 2 | AI20: {=SUM(C20:AH20)} -> 2
A21: 12 | B21: [ADC10S02] Adiacontrol Extraction Positive Control BVDV EAR | H21: 1 | U21: 1 | AI21: {=SUM(C21:AH21)} -> 2
A22: 13 | B22: [ADI016-100] ADIAVET™ MYCO AV FAST TIME | C22: 1 | Q22: 1 | R22: 2 | T22: 3 | U22: 2 | W22: 2 | X22: 2 | Z22: 2 | AA22: 2 | AB22: 3 | AD22: 4 | AI22: {=SUM(C22:AH22)} -> 24
A23: 14 | B23: [ADI016-500] ADIAVET™ MYCO AV FAST TIME | AF23: 2 | AG23: 1 | AH23: 1 | AI23: {=SUM(C23:AH23)} -> 4
A24: 15 | B24: [ADI033-100] ADIAVET™ APP REAL TIME | K24: 1 | Z24: 1 | AI24: {=SUM(C24:AH24)} -> 2
A25: 16 | B25: [ADI045-100] ADIAVET™ PARATB REAL TIME | C25: 8 | D25: 2 | E25: 1 | F25: 2 | G25: 4 | H25: 1 | I25: 7 | K25: 2 | L25: 3 | M25: 2 | N25: 5 | O25: 7 | Q25: 3 | R25: 2 | T25: 3 | U25: 1 | V25: 2 | X25: 2 | Y25: 1 | Z25: 3 | AA25: 4 | AC25: 2 | AD25: 3 | AE25: 4 | AF25: 1 | AG25: 3 | AI25: {=SUM(C25:AH25)} -> 78
A26: 17 | B26: [ADI072-100] ADIAVET™ PRV REAL TIME | R26: 1 | AI26: {=SUM(C26:AH26)} -> 1
A27: 18 | B27: [ADI105-100] ADIAVET™ BVDV REAL TIME | J27: 1 | N27: 11 | T27: 2 | AA27: 1 | AC27: 5 | AG27: 7 | AI27: {=SUM(C27:AH27)} -> 27
A28: 19 | B28: [ADI105-500] ADIAVET™ BVDV REAL TIME | C28: 9 | D28: 7 | E28: 10 | F28: 5 | G28: 12 | H28: 3 | I28: 20 | J28: 11 | K28: 11 | L28: 10 | M28: 9 | O28: 7 | P28: 10 | Q28: 6 | R28: 9 | S28: 9 | T28: 11 | U28: 12 | V28: 9 | W28: 8 | X28: 9 | Y28: 4 | Z28: 8 | AA28: 13 | AB28: 6 | AC28: 10 | AD28: 8 | AE28: 8 | AF28: 12 | AH28: 9 | AI28: {=SUM(C28:AH28)} -> 275
A29: 20 | B29: [ADI106-100] ADIAVET BVDV FAST TIME 100R (historique) | AI29: {=SUM(C29:AH29)} -> 0
A30: 21 | B30: [ADI122-100] ADIAVET™ SALMO FAST TIME | AI30: {=SUM(C30:AH30)} -> 0
A31: 22 | B31: [ADI143-100] ADIAVET™ COXIELLA REAL TIME | C31: 5 | D31: 5 | E31: 7 | F31: 2 | G31: 7 | H31: 6 | I31: 6 | J31: 7 | K31: 7 | L31: 3 | M31: 4 | N31: 5 | O31: 2 | P31: 5 | Q31: 4 | R31: 6 | S31: 5 | T31: 4 | U31: 6 | V31: 5 | X31: 1 | Y31: 4 | Z31: 4 | AA31: 8 | AB31: 4 | AC31: 4 | AD31: 4 | AE31: 7 | AF31: 2 | AG31: 7 | AI31: {=SUM(C31:AH31)} -> 146
A32: 23 | B32: [ADI273-100] ADIAVET™ TOXO FAST TIME | E32: 20 | H32: 10 | L32: 10 | N32: 10 | O32: 10 | Q32: 10 | T32: 10 | V32: 10 | X32: 10 | Z32: 10 | AA32: 10 | AC32: 10 | AE32: 10 | AG32: 10 | AH32: 10 | AI32: {=SUM(C32:AH32)} -> 160
A33: 24 | B33: [ADI282-100] ADIAVET™ SIV REAL TIME | C33: 1 | I33: 1 | L33: 2 | O33: 1 | T33: 1 | Y33: 1 | Z33: 2 | AE33: 1 | AI33: {=SUM(C33:AH33)} -> 10
A34: 25 | B34: [ADI283-100] ADIAVET™ AIV REAL TIME | D34: 10 | G34: 2 | L34: 4 | N34: 4 | O34: 7 | X34: 2 | Y34: 3 | AI34: {=SUM(C34:AH34)} -> 32
A35: 26 | B35: [ADI352-100] ADIAVET™ BTV REAL TIME | I35: 6 | J35: 4 | L35: 3 | M35: 4 | N35: 4 | O35: 1 | P35: 4 | S35: 11 | T35: 3 | V35: 1 | X35: 1 | Z35: 3 | AC35: 1 | AI35: {=SUM(C35:AH35)} -> 46
A36: 27 | B36: [ADI352-500] ADIAVET™ BTV REAL TIME | C36: 1 | D36: 1 | G36: 6 | H36: 4 | I36: 6 | O36: 2 | Q36: 1 | R36: 1 | S36: 1 | AA36: 6 | AC36: 2 | AE36: 5 | AI36: {=SUM(C36:AH36)} -> 36
A37: 28 | B37: [ADI381-100] ADIAVET™ BTV TYPE 8 REAL TIME | G37: 6 | H37: 12 | L37: 1 | M37: 1 | P37: 2 | R37: 2 | AI37: {=SUM(C37:AH37)} -> 24
A38: 29 | B38: [ADI381-50] ADIAVET™ BTV TYPE 8 REAL TIME | R38: 2 | S38: 1 | AB38: 2 | AC38: 1 | AI38: {=SUM(C38:AH38)} -> 6
A39: 30 | B39: [ADI451-100] ADIAVET™ BESNOITIA REAL TIME | AI39: {=SUM(C39:AH39)} -> 0
A40: 31 | B40: [ADI471-100] ADIAVET WEST NILE REAL TIME 100R (historique) | AI40: {=SUM(C40:AH40)} -> 0
...

Sheet Filtres actifs
A1: Filter | B1: Value
A2: Partenaire | B2: LABOKLIN GMBH & CO.KG, LABOKLIN GMBH & CO.KG, Celina WALL, LABOKLIN GMBH & CO.KG, Tobias MALAN, LABOKLIN GMBH & CO.KG, Katharina KERNER, LABOKLIN GMBH & CO.KG, Michaela GENTIL, LABOKLIN GMBH & CO.KG, Corinna WEBER, Gip Labeo, Gip Labeo, LABEO Franck DUNCOMBE LDA14, Gip Labeo, Fabien MISZCZAK, Gip Labeo, LABEO site de la Manche LDA50, Gip Labeo, Fabienne BENOIT, Gip Labeo, Delphine PERROTTE, Gip Labeo, Magali PETIT, Gip Labeo, LABEO Site de l'Orne LDA61, LABOKLIN GMBH & CO.KG, Nora MÜLLER, Gip Labeo, Labeo Logistique, Gip Labeo, Didier GARDINIER, Gip Labeo, Virginie JOUVIN, Gip Labeo, Marie LE ROY, Gip Labeo, Emmanuelle LOTH, Gip Labeo, Marlène MOREAU, Gip Labeo, 61PSVB - Secteur Biologie Moléculaire LABÉO, Gip Labeo, Maeva CHERIF FEILDEL, Gip Labeo, Delphine TUDAL, Gip Labeo, Nadège DAGUIER, Gip Labeo, Céline LE GLATIN-COULON, Gip Labeo, Alexandra LIMA, Laboklin Polska Sp z o o, Aneta Bieleniewicz-Kamińska, Gip Labeo, LABEO Site de l'Eure LDA27, Gip Labeo, Antoine DURIEUX, Gip Labeo, Franck DENOS, LABOKLIN GMBH & CO.KG, Dominik PFISTER, LABOKLIN GMBH & CO.KG, Frau Teresa GERHARD, Gip Labeo, Corinne LEBRET, LABOKLIN GMBH & CO.KG, Dr. Petra KÜHNLEIN, Gip Labeo, Albertine LEON-SECK, Gip Labeo, Hugo BEVAN, Gip Labeo, David GERMAIN, Gip Labeo, Nadège NICOLLE, Gip Labeo, LO PS Virologie, Gip Labeo, Aurélia GRANDIDIER, Gip Labeo, Michael MARGUERIE, Gip Labeo, Fanny GALLIENNE, Gip Labeo, Béatrice LABONNE, Gip Labeo, Nadege ROUSSEAU, Gip Labeo, Amélie DELAFOSSE, Gip Labeo, Service Immunologie, Gip Labeo, Service Immunologie, Gip Labeo, Aglae LECLUSE, LABOKLIN GMBH & CO.KG, Kerstin KEUNE, Gip Labeo, Flora CARNET, Gip Labeo, Accueil clients, Gip Labeo, Accueil clients, Gip Labeo, Accueil clients, Gip Labeo, Fabienne DEGOUET, Gip Labeo, Dylan LECHAFFETOIS
A3: Pays
A4: Produit
A5: Start Date (08/31/2025) | B5: 01/31/2026
A6: Catégorie mère Studio
A7: Catégorie de produit
